{
 "cells": [
  {
   "cell_type": "code",
   "execution_count": 13,
   "metadata": {},
   "outputs": [],
   "source": [
    "import boto3\n",
    "import pandas as pd\n",
    "import psycopg2\n",
    "from psycopg2 import OperationalError\n",
    "import os\n",
    "from dotenv import load_dotenv"
   ]
  },
  {
   "cell_type": "code",
   "execution_count": 4,
   "metadata": {},
   "outputs": [],
   "source": [
    "bucket_name = \"kayak-final-projet\"  # Remplace avec ton bucket S3\n",
    "file_name = \"geolocalisation.csv\"  # Le fichier local\n",
    "s3_key = file_name # Chemin dans S3 (optionnel)"
   ]
  },
  {
   "cell_type": "code",
   "execution_count": 5,
   "metadata": {},
   "outputs": [],
   "source": [
    "# Charger les variables du fichier .env\n",
    "load_dotenv()\n",
    "\n",
    "# Récupérer les valeurs des variables\n",
    "aws_access_key = os.getenv(\"AWS_ACCESS_KEY_ID\")\n",
    "aws_secret_key = os.getenv(\"AWS_SECRET_ACCESS_KEY\")\n",
    "aws_region = os.getenv(\"AWS_DEFAULT_REGION\")\n",
    "aws_bd_password = os.getenv(\"DB_PASSWORD\")\n",
    "\n",
    "# Initialiser le client Boto3 avec les credentials\n",
    "s3_client = boto3.client(\n",
    "    \"s3\",\n",
    "    aws_access_key_id=aws_access_key,\n",
    "    aws_secret_access_key=aws_secret_key,\n",
    "    region_name=aws_region,\n",
    ")"
   ]
  },
  {
   "cell_type": "code",
   "execution_count": 25,
   "metadata": {},
   "outputs": [
    {
     "name": "stdout",
     "output_type": "stream",
     "text": [
      "Erreur de connexion : connection to server at \"database-2.clwqcisew0ya.eu-west-3.rds.amazonaws.com\" (13.39.185.50), port 5432 failed: Connection timed out (0x0000274C/10060)\n",
      "\tIs the server running on that host and accepting TCP/IP connections?\n",
      "\n"
     ]
    }
   ],
   "source": [
    "\n",
    "# Remplace ces valeurs par les tiennes\n",
    "DB_HOST = \"database-2.clwqcisew0ya.eu-west-3.rds.amazonaws.com\"\n",
    "DB_PORT = 5432  # 3306 pour MySQL, 5432 pour PostgreSQL\n",
    "DB_NAME = \"database-2\"\n",
    "DB_USER = \"postgres\"\n",
    "\n",
    "def test_connection():\n",
    "    try:\n",
    "        conn = psycopg2.connect(\n",
    "                host=DB_HOST,\n",
    "                port=DB_PORT,\n",
    "                user=DB_USER,\n",
    "                password='Wailou2825!',\n",
    "                dbname=DB_NAME\n",
    "            )        \n",
    "        print(\"Connexion réussie !\")\n",
    "        conn.close()\n",
    "    \n",
    "    except Exception as e:\n",
    "        print(f\"Erreur de connexion : {e}\")\n",
    "\n",
    "if __name__ == \"__main__\":\n",
    "    test_connection()\n"
   ]
  },
  {
   "cell_type": "code",
   "execution_count": 23,
   "metadata": {},
   "outputs": [],
   "source": [
    "def lambda_handler(bucket, key):\n",
    "    \n",
    "    # Télécharger le fichier depuis S3\n",
    "    obj = s3_client.get_object(Bucket=bucket, Key=key)\n",
    "    df = pd.read_csv(obj['Body'])\n",
    "\n",
    "    # Connexion à la base RDS\n",
    "    conn = psycopg2.connect(\n",
    "        host=\"ep-cold-cake-a2wb8s4t-pooler.eu-central-1.aws.neon.tech\",\n",
    "        user=\"neondb_owner\",\n",
    "        password=\"vRUyZpx1q3kT\",\n",
    "        database=\"neondb\",\n",
    "        sslmode=\"require\"\n",
    "    )\n",
    "\n",
    "    with conn.cursor() as cursor:\n",
    "        for _, row in df.iterrows():\n",
    "            cursor.execute(\"INSERT INTO villes (adresse, longitude, latitude) VALUES (%s, %s)\", (row['adresse'], row['longitude'], row['latitude']))\n",
    "        \n",
    "    conn.commit()\n",
    "    conn.close()\n"
   ]
  },
  {
   "cell_type": "code",
   "execution_count": 30,
   "metadata": {},
   "outputs": [
    {
     "ename": "ClientError",
     "evalue": "An error occurred (AccessDenied) when calling the GetObject operation: User: arn:aws:iam::211125397832:user/postgres is not authorized to perform: s3:GetObject on resource: \"arn:aws:s3:::kayak-final-projet/geolocalisation.csv\" because no permissions boundary allows the s3:GetObject action",
     "output_type": "error",
     "traceback": [
      "\u001b[1;31m---------------------------------------------------------------------------\u001b[0m",
      "\u001b[1;31mClientError\u001b[0m                               Traceback (most recent call last)",
      "Cell \u001b[1;32mIn[30], line 1\u001b[0m\n\u001b[1;32m----> 1\u001b[0m \u001b[43mlambda_handler\u001b[49m\u001b[43m(\u001b[49m\u001b[43mbucket_name\u001b[49m\u001b[43m,\u001b[49m\u001b[43m \u001b[49m\u001b[43ms3_key\u001b[49m\u001b[43m)\u001b[49m\n",
      "Cell \u001b[1;32mIn[23], line 4\u001b[0m, in \u001b[0;36mlambda_handler\u001b[1;34m(bucket, key)\u001b[0m\n\u001b[0;32m      1\u001b[0m \u001b[38;5;28;01mdef\u001b[39;00m \u001b[38;5;21mlambda_handler\u001b[39m(bucket, key):\n\u001b[0;32m      2\u001b[0m     \n\u001b[0;32m      3\u001b[0m     \u001b[38;5;66;03m# Télécharger le fichier depuis S3\u001b[39;00m\n\u001b[1;32m----> 4\u001b[0m     obj \u001b[38;5;241m=\u001b[39m \u001b[43ms3_client\u001b[49m\u001b[38;5;241;43m.\u001b[39;49m\u001b[43mget_object\u001b[49m\u001b[43m(\u001b[49m\u001b[43mBucket\u001b[49m\u001b[38;5;241;43m=\u001b[39;49m\u001b[43mbucket\u001b[49m\u001b[43m,\u001b[49m\u001b[43m \u001b[49m\u001b[43mKey\u001b[49m\u001b[38;5;241;43m=\u001b[39;49m\u001b[43mkey\u001b[49m\u001b[43m)\u001b[49m\n\u001b[0;32m      5\u001b[0m     df \u001b[38;5;241m=\u001b[39m pd\u001b[38;5;241m.\u001b[39mread_csv(obj[\u001b[38;5;124m'\u001b[39m\u001b[38;5;124mBody\u001b[39m\u001b[38;5;124m'\u001b[39m])\n\u001b[0;32m      7\u001b[0m     \u001b[38;5;66;03m# Connexion à la base RDS\u001b[39;00m\n",
      "File \u001b[1;32m~\\AppData\\Local\\Packages\\PythonSoftwareFoundation.Python.3.11_qbz5n2kfra8p0\\LocalCache\\local-packages\\Python311\\site-packages\\botocore\\client.py:569\u001b[0m, in \u001b[0;36mClientCreator._create_api_method.<locals>._api_call\u001b[1;34m(self, *args, **kwargs)\u001b[0m\n\u001b[0;32m    565\u001b[0m     \u001b[38;5;28;01mraise\u001b[39;00m \u001b[38;5;167;01mTypeError\u001b[39;00m(\n\u001b[0;32m    566\u001b[0m         \u001b[38;5;124mf\u001b[39m\u001b[38;5;124m\"\u001b[39m\u001b[38;5;132;01m{\u001b[39;00mpy_operation_name\u001b[38;5;132;01m}\u001b[39;00m\u001b[38;5;124m() only accepts keyword arguments.\u001b[39m\u001b[38;5;124m\"\u001b[39m\n\u001b[0;32m    567\u001b[0m     )\n\u001b[0;32m    568\u001b[0m \u001b[38;5;66;03m# The \"self\" in this scope is referring to the BaseClient.\u001b[39;00m\n\u001b[1;32m--> 569\u001b[0m \u001b[38;5;28;01mreturn\u001b[39;00m \u001b[38;5;28;43mself\u001b[39;49m\u001b[38;5;241;43m.\u001b[39;49m\u001b[43m_make_api_call\u001b[49m\u001b[43m(\u001b[49m\u001b[43moperation_name\u001b[49m\u001b[43m,\u001b[49m\u001b[43m \u001b[49m\u001b[43mkwargs\u001b[49m\u001b[43m)\u001b[49m\n",
      "File \u001b[1;32m~\\AppData\\Local\\Packages\\PythonSoftwareFoundation.Python.3.11_qbz5n2kfra8p0\\LocalCache\\local-packages\\Python311\\site-packages\\botocore\\client.py:1023\u001b[0m, in \u001b[0;36mBaseClient._make_api_call\u001b[1;34m(self, operation_name, api_params)\u001b[0m\n\u001b[0;32m   1019\u001b[0m     error_code \u001b[38;5;241m=\u001b[39m error_info\u001b[38;5;241m.\u001b[39mget(\u001b[38;5;124m\"\u001b[39m\u001b[38;5;124mQueryErrorCode\u001b[39m\u001b[38;5;124m\"\u001b[39m) \u001b[38;5;129;01mor\u001b[39;00m error_info\u001b[38;5;241m.\u001b[39mget(\n\u001b[0;32m   1020\u001b[0m         \u001b[38;5;124m\"\u001b[39m\u001b[38;5;124mCode\u001b[39m\u001b[38;5;124m\"\u001b[39m\n\u001b[0;32m   1021\u001b[0m     )\n\u001b[0;32m   1022\u001b[0m     error_class \u001b[38;5;241m=\u001b[39m \u001b[38;5;28mself\u001b[39m\u001b[38;5;241m.\u001b[39mexceptions\u001b[38;5;241m.\u001b[39mfrom_code(error_code)\n\u001b[1;32m-> 1023\u001b[0m     \u001b[38;5;28;01mraise\u001b[39;00m error_class(parsed_response, operation_name)\n\u001b[0;32m   1024\u001b[0m \u001b[38;5;28;01melse\u001b[39;00m:\n\u001b[0;32m   1025\u001b[0m     \u001b[38;5;28;01mreturn\u001b[39;00m parsed_response\n",
      "\u001b[1;31mClientError\u001b[0m: An error occurred (AccessDenied) when calling the GetObject operation: User: arn:aws:iam::211125397832:user/postgres is not authorized to perform: s3:GetObject on resource: \"arn:aws:s3:::kayak-final-projet/geolocalisation.csv\" because no permissions boundary allows the s3:GetObject action"
     ]
    }
   ],
   "source": [
    "lambda_handler(bucket_name, s3_key)"
   ]
  },
  {
   "cell_type": "code",
   "execution_count": null,
   "metadata": {},
   "outputs": [],
   "source": [
    "db = pymysql.connect(\n",
    "    host=\"database-2.clwqcisew0ya.eu-west-3.rds.amazonaws.com\",\n",
    "    port=3306,\n",
    "    user=\"admin\",\n",
    "    password=aws_bd_password,\n",
    "    database=\"database-2\"\n",
    ")"
   ]
  },
  {
   "cell_type": "code",
   "execution_count": 22,
   "metadata": {},
   "outputs": [],
   "source": [
    "# postgresql://neondb_owner:vRUyZpx1q3kT@ep-cold-cake-a2wb8s4t-pooler.eu-central-1.aws.neon.tech/neondb?sslmode=require\n",
    "\n",
    "db = psycopg2.connect(\n",
    "    host=\"ep-cold-cake-a2wb8s4t-pooler.eu-central-1.aws.neon.tech\",\n",
    "    user=\"neondb_owner\",\n",
    "    password=\"vRUyZpx1q3kT\",\n",
    "    database=\"neondb\",\n",
    "    sslmode=\"require\"\n",
    ")"
   ]
  }
 ],
 "metadata": {
  "kernelspec": {
   "display_name": "Python 3",
   "language": "python",
   "name": "python3"
  },
  "language_info": {
   "codemirror_mode": {
    "name": "ipython",
    "version": 3
   },
   "file_extension": ".py",
   "mimetype": "text/x-python",
   "name": "python",
   "nbconvert_exporter": "python",
   "pygments_lexer": "ipython3",
   "version": "3.13.1"
  }
 },
 "nbformat": 4,
 "nbformat_minor": 2
}
